Workbook

Sheet Исходные
A1: Исходные данные и допущения
A2: Синие ячейки редактируются. Товарные цены — допущения, не найденные прайсы. Изменение исходных величин пересчитывает связанные строки; фиксированные метражи трасс уточняются вручную.
A4: Параметр | B4: Значение | C4: Единица | D4: Основание/ограничение
A5: Лимит с резервом | B5: 7000000 | C5: ₸ | D5: Без крупной техники
A6: Резерв | B6: 700000 | C6: ₸ | D6: 10% лимита; не 10% любой итоговой суммы
A7: Площадь для оплаты работы | B7: 41 | C7: м² | D7: Допущение договора; полезная 38,8, учётная 40,7
A8: Ставка бригады | B8: 50000 | C8: ₸/м² | D8: От пользователя; материалы считаются отдельно
A9: Жилая комната | B9: 20.5 | C9: м² | D9: По экспликации
A10: Кухня | B10: 8.9 | C10: м² | D10: По экспликации, остаётся на месте
A11: Прихожая | B11: 4.3 | C11: м² | D11: По экспликации
A12: Санузел | B12: 5.1 | C12: м² | D12: По экспликации
A13: Стены под покраску, нетто | B13: 96 | C13: м² | D13: Предварительно; проверить проёмы/развёртки
A14: Сухие зоны под штукатурку | B14: 86 | C14: м² | D14: Неизвестно, насколько нужна новая штукатурка
A15: Влажные зоны под штукатурку | B15: 25 | C15: м² | D15: Предварительная площадь
A16: Облицовка стен ванной | B16: 23 | C16: м² | D16: Предварительная площадь
... A27: Площадь гидроизоляции | B27: 16 | C27: м² | D27: Пол + подъёмы + мокрые стены; проверить схему

Sheet Покупки
A1: Предварительная ведомость материалов и работ
A2: Все товарные ставки — расчётные ориентиры. Низкая/базовая/высокая цена — чувствительность, не рыночные котировки. Синие ячейки редактируются. Монтажные работы повторно не добавлены к цене бригады.
A4: № | B4: Группа | C4: Материал / статья | D4: Количество | E4: Единица | F4: Низкая цена | G4: Базовая цена | H4: Высокая цена | I4: Низкая сумма | J4: Базовая сумма | K4: Высокая сумма | L4: Расчёт / комплектация | M4: Статус цены
A5: 1 | B5: Работа | C5: Комплекс работ бригады | D5: ='Исходные'!$B$7 -> 41 | E5: м² | F5: ='Исходные'!$B$8 -> 50000 | G5: ='Исходные'!$B$8 -> 50000 | H5: ='Исходные'!$B$8 -> 50000 | I5: =D5*F5 -> 2050000 | J5: =D5*G5 -> 2050000 | K5: =D5*H5 -> 2050000 | L5: Ставка пользователя; материалы считаются отдельно. Электрика, сантехника и подготовка стен включены; спецработы подтвердить в перечне. | M5: Ставка работ — пользователь; площадь расчётная
A6: 2 | B6: Основания и стены | C6: Гипсовая штукатурка для сухих зон, 30 кг | D6: =ROUNDUP('Исходные'!$B$14*8.5*'Исходные'!$B$21/10*(1+'Исходные'!$B$23)/30,0) -> 27 | E6: меш. | F6: 3600 | G6: 4500 | H6: 5625 | I6: =D6*F6 -> 97200 | J6: =D6*G6 -> 121500 | K6: =D6*H6 -> 151875 | L6: 86 м² × 8,5 кг/м² при 10 мм × 1,10 / 30; округление вверх. Расход уточнить по продукту. | M6: Расчётный ориентир; прайс не проверен
A7: 3 | B7: Основания и стены | C7: Цементная штукатурка для влажных зон, 25 кг | D7: =ROUNDUP('Исходные'!$B$15*12*'Исходные'!$B$22/10*(1+'Исходные'!$B$23)/25,0) -> 14 | E7: меш. | F7: 3040 | G7: 3800 | H7: 4750 | I7: =D7*F7 -> 42560 | J7: =D7*G7 -> 53200 | K7: =D7*H7 -> 66500 | L7: 25 м² × 12 кг/м² при 10 мм × 1,10 / 25; проверить совместимость с основанием. | M7: Расчётный ориентир; прайс не проверен
A8: 4 | B8: Основания и стены | C8: Финишная шпаклёвка, 20 кг | D8: =ROUNDUP(('Исходные'!$B$13+('Исходные'!$B$9+'Исходные'!$B$10+'Исходные'!$B$11+'Исходные'!$B$12))*2*(1+'Исходные'!$B$23)/20,0) -> 15 | E8: меш. | F8: 4800 | G8: 6000 | H8: 7500 | I8: =D8*F8 -> 72000 | J8: =D8*G8 -> 90000 | K8: =D8*H8 -> 112500 | L8: (96 м² стен + 38,8 м² потолков) × 2 кг/м² × 1,10 / 20; условный расход всего слоя. | M8: Расчётный ориентир; прайс не проверен
A9: 5 | B9: Основания и стены | C9: Грунт под штукатурку/шпаклёвку/краску | D9: 30 | E9: л | F9: 960 | G9: 1200 | H9: 1500 | I9: =D9*F9 -> 28800 | J9: =D9*G9 -> 36000 | K9: =D9*H9 -> 45000 | L9: Несколько совместимых продуктов под разные основания; не одна универсальная грунтовка. | M9: Расчётный ориентир; прайс не проверен
A10: 6 | B10: Основания и стены | C10: Малярный стеклохолст 40–50 г/м², рулон 50 м² | D10: =ROUNDUP('Исходные'!$B$13*(1+'Исходные'!$B$23)/50,0) -> 3 | E10: рул. | F10: 14400 | G10: 18000 | H10: 22500 | I10: =D10*F10 -> 43200 | J10: =D10*G10 -> 54000 | K10: =D10*H10 -> 67500 | L10: 96 м² × 1,10 = 105,6 м²; 3 рулона. Только по совместимой системе; не защищает от активных трещин. | M10: Расчётный ориентир; прайс не проверен
A11: 7 | B11: Основания и стены | C11: Клей для стеклохолста | D11: 15 | E11: кг | F11: 1440 | G11: 1800 | H11: 2250 | I11: =D11*F11 -> 21600 | J11: =D11*G11 -> 27000 | K11: =D11*H11 -> 33750 | L11: Расход и необходимость шпаклёвки поверх — по технологии производителя. | M11: Расчётный ориентир; прайс не проверен
A12: 8 | B12: Основания и стены | C12: Моющаяся матовая краска стен, класс мокрого истирания 1–2 | D12: =CEILING('Исходные'!$B$13*'Исходные'!$B$25/'Исходные'!$B$24*(1+'Исходные'!$B$23),10) -> 30 | E12: л | F12: 2800 | G12: 3500 | H12: 4375 | I12: =D12*F12 -> 84000 | J12: =D12*G12 -> 105000 | K12: =D12*H12 -> 131250 | L12: 96 м² × 2 слоя / 10 м²/л × 1,10 = 21,12 л; 3×10 л на закупку с запасом и колеровкой. | M12: Расчётный ориентир; прайс не проверен
A13: 9 | B13: Основания и стены | C13: Краска потолков | D13: =CEILING(('Исходные'!$B$9+'Исходные'!$B$10+'Исходные'!$B$11+'Исходные'!$B$12)*'Исходные'!$B$25/'Исходные'!$B$26*(1+'Исходные'!$B$23),5) -> 15 | E13: л | F13: 1600 | G13: 2000 | H13: 2500 | I13: =D13*F13 -> 24000 | J13: =D13*G13 -> 30000 | K13: =D13*H13 -> 37500 | L13: 38,8 м² × 2 / 8 × 1,10 = 10,67 л; закупка 15 л. | M13: Расчётный ориентир; прайс не проверен
A14: 10 | B14: Основания и стены | C14: Ленты стыков, уголки, абразив, герметики и расходники | D14: 1 | E14: компл. | F14: 32000 | G14: 40000 | H14: 50000 | I14: =D14*F14 -> 32000 | J14: =D14*G14 -> 40000 | K14: =D14*H14 -> 50000 | L14: Армировать стыки по системе; конструкционные швы сохранять. | M14: Расчётный ориентир; прайс не проверен
A15: 11 | B15: Полы и плитка | C15: Финишный ровнитель пола, 25 кг | D15: =ROUNDUP(('Исходные'!$B$9+'Исходные'!$B$10+'Исходные'!$B$11+'Исходные'!$B$12)*'Исходные'!$B$20*1.6*(1+'Исходные'!$B$23)/25,0) -> 14 | E15: меш. | F15: 3600 | G15: 4500 | H15: 5625 | I15: =D15*F15 -> 50400 | J15: =D15*G15 -> 63000 | K15: =D15*H15 -> 78750 | L15: 38,8 м² × 5 мм × 1,6 кг/м²/мм × 1,10 / 25; предполагается пригодная базовая стяжка. | M15: Расчётный ориентир; прайс не проверен
A16: 12 | B16: Полы и плитка | C16: Ламинат 8–10 мм, класс 32/AC4 или 33/AC5 | D16: =ROUNDUP('Исходные'!$B$9*(1+'Исходные'!$B$23),0) -> 23 | E16: м² | F16: 5200 | G16: 6500 | H16: 8125 | I16: =D16*F16 -> 119600 | J16: =D16*G16 -> 149500 | K16: =D16*H16 -> 186875 | L16: 20,5 м² × 1,10 = 22,55 м²; точная закупка по площади упаковки. В кухне и прихожей — плитка. | M16: Расчётный ориентир; прайс не проверен
A17: 13 | B17: Полы и плитка | C17: Подложка под ламинат и пароизоляция по инструкции | D17: =ROUNDUP('Исходные'!$B$9*(1+'Исходные'!$B$23),0) -> 23 | E17: м² | F17: 720 | G17: 900 | H17: 1125 | I17: =D17*F17 -> 16560 | J17: =D17*G17 -> 20700 | K17: =D17*H17 -> 25875 | L17: Подложка обычно 1,5–3 мм; толщина и прочность по требованиям замка, не мягкая толстая пена. | M17: Расчётный ориентир; прайс не проверен
A18: 14 | B18: Полы и плитка | C18: Плинтус с комплектующими | D18: 34 | E18: пог. м | F18: 960 | G18: 1200 | H18: 1500 | I18: =D18*F18 -> 32640 | J18: =D18*G18 -> 40800 | K18: =D18*H18 -> 51000 | L18: Предварительный обмер; не крепить одновременно к плавающему полу и стене. | M18: Расчётный ориентир; прайс не проверен
A19: 15 | B19: Полы и плитка | C19: Напольный керамогранит кухни/прихожей/санузла | D19: =ROUNDUP(('Исходные'!$B$10+'Исходные'!$B$11+'Исходные'!$B$12)*(1+'Исходные'!$B$23),0) -> 21 | E19: м² | F19: 4800 | G19: 6000 | H19: 7500 | I19: =D19*F19 -> 100800 | J19: =D19*G19 -> 126000 | K19: =D19*H19 -> 157500 | L19: (8,9 + 4,3 + 5,1) × 1,10 = 20,13 м²; остаток из упаковок; лоджия не включена. | M19: Расчётный ориентир; прайс не проверен
A20: 16 | B20: Полы и плитка | C20: Настенная плитка санузла | D20: =ROUNDUP('Исходные'!$B$16*(1+'Исходные'!$B$23),0) -> 26 | E20: м² | F20: 5200 | G20: 6500 | H20: 8125 | I20: =D20*F20 -> 135200 | J20: =D20*G20 -> 169000 | K20: =D20*H20 -> 211250 | L20: 23 м² облицовки × 1,10 = 25,3 м²; уточнить развёртки и размеры плитки. | M20: Расчётный ориентир; прайс не проверен
A21: 17 | B21: Полы и плитка | C21: Плитка кухонного фартука | D21: =ROUNDUP('Исходные'!$B$17*(1+'Исходные'!$B$23),0) -> 3 | E21: м² | F21: 5200 | G21: 6500 | H21: 8125 | I21: =D21*F21 -> 15600 | J21: =D21*G21 -> 19500 | K21: =D21*H21 -> 24375 | L21: 2,5 м² × 1,10 = 2,75 м². | M21: Расчётный ориентир; прайс не проверен
A22: 18 | B22: Полы и плитка | C22: Клей для плитки, 25 кг | D22: =ROUNDUP(('Исходные'!$B$10+'Исходные'!$B$11+'Исходные'!$B$12+'Исходные'!$B$16+'Исходные'!$B$17)*4.5*(1+'Исходные'!$B$23)/25,0) -> 9 | E22: меш. | F22: 4800 | G22: 6000 | H22: 7500 | I22: =D22*F22 -> 43200 | J22: =D22*G22 -> 54000 | K22: =D22*H22 -> 67500 | L22: (18,3 + 23 + 2,5) × 4,5 кг/м² × 1,10 / 25; размер зуба, формат и основание уточнить. | M22: Расчётный ориентир; прайс не проверен
A23: 19 | B23: Полы и плитка | C23: Затирка, санитарный силикон, профили примыканий | D23: 1 | E23: компл. | F23: 28000 | G23: 35000 | H23: 43750 | I23: =D23*F23 -> 28000 | J23: =D23*G23 -> 35000 | K23: =D23*H23 -> 43750 | L23: Эластичные примыкания; силикон не заменяет гидроизоляцию. | M23: Расчётный ориентир; прайс не проверен
A24: 20 | B24: Полы и плитка | C24: Обмазочная гидроизоляция | D24: =CEILING('Исходные'!$B$27*1.5*(1+'Исходные'!$B$23),10) -> 30 | E24: кг | F24: 1840 | G24: 2300 | H24: 2875 | I24: =D24*F24 -> 55200 | J24: =D24*G24 -> 69000 | K24: =D24*H24 -> 86250 | L24: Условно 16 м² × 1,5 кг/м² на систему × 1,10 = 26,4 кг; слои по инструкции. | M24: Расчётный ориентир; прайс не проверен
A25: 21 | B25: Полы и плитка | C25: Гидроизоляционная лента и манжеты проходок | D25: 1 | E25: компл. | F25: 24000 | G25: 30000 | H25: 37500 | I25: =D25*F25 -> 24000 | J25: =D25*G25 -> 30000 | K25: =D25*H25 -> 37500 | L25: Ориентир 15 м ленты + манжеты; контроль примыканий к ванне. | M25: Расчётный ориентир; прайс не проверен
A26: 22 | B26: Шумоизоляция и потолки | C26: Виброподвесы потолка гостиной | D26: 40 | E26: шт. | F26: 2800 | G26: 3500 | H26: 4375 | I26: =D26*F26 -> 112000 | J26: =D26*G26 -> 140000 | K26: =D26*H26 -> 175000 | L26: На 20,5 м²; число и допустимую нагрузку определить по выбранной испытанной системе. | M26: Расчётный ориентир; прайс не проверен
A27: 23 | B27: Шумоизоляция и потолки | C27: Акустическая минвата 50 мм потолка | D27: =ROUNDUP('Исходные'!$B$9*(1+'Исходные'!$B$23),0) -> 23 | E27: м² | F27: 1600 | G27: 2000 | H27: 2500 | I27: =D27*F27 -> 36800 | J27: =D27*G27 -> 46000 | K27: =D27*H27 -> 57500 | L27: 20,5 × 1,10; плотность и состав — по системе, сама вата не является звукоизоляционной преградой. | M27: Расчётный ориентир; прайс не проверен
A28: 24 | B28: Шумоизоляция и потолки | C28: Двухслойная листовая обшивка потолка | D28: =ROUNDUP(2*'Исходные'!$B$9*(1+'Исходные'!$B$23),0) -> 46 | E28: м² слоя | F28: 1440 | G28: 1800 | H28: 2250 | I28: =D28*F28 -> 66240 | J28: =D28*G28 -> 82800 | K28: =D28*H28 -> 103500 | L28: 2 × 20,5 × 1,10 = 45,1 м²; ГКЛ/ГВЛ по системе. Не считать как 46 м² потолка. | M28: Расчётный ориентир; прайс не проверен
A29: 25 | B29: Шумоизоляция и потолки | C29: Профили потолка, лента, акустический герметик, крепёж | D29: 1 | E29: компл. | F29: 72000 | G29: 90000 | H29: 112500 | I29: =D29*F29 -> 72000 | J29: =D29*G29 -> 90000 | K29: =D29*H29 -> 112500 | L29: Полный развязанный каркас; раскладка и масса по монтажной карте. | M29: Расчётный ориентир; прайс не проверен
A30: 26 | B30: Шумоизоляция и потолки | C30: Каркасная шумоизоляция одной стены: материалы | D30: =ROUNDUP('Исходные'!$B$19*'Исходные'!$B$18,0) -> 9 | E30: м² | F30: 9600 | G30: 12000 | H30: 15000 | I30: =D30*F30 -> 86400 | J30: =D30*G30 -> 108000 | K30: =D30*H30 -> 135000 | L30: Условно стена 3,1 × 2,8 = 8,68 м². Комплект: каркас, вата, 2 слоя листов, лента и герметик; отделка уже в общей смете. | M30: Расчётный ориентир; прайс не проверен
A31: 27 | B31: Шумоизоляция и потолки | C31: Обычный листовой потолок остальных помещений: материалы | D31: =('Исходные'!$B$9+'Исходные'!$B$10+'Исходные'!$B$11+'Исходные'!$B$12)-'Исходные'!$B$9 -> 18.3 | E31: м² | F31: 2800 | G31: 3500 | H31: 4375 | I31: =D31*F31 -> 51240 | J31: =D31*G31 -> 64050 | K31: =D31*H31 -> 80062.5 | L31: Кухня/прихожая/санузел; влагостойкая система в мокрой зоне. Финишная отделка учтена выше. | M31: Расчётный ориентир; прайс не проверен
A32: 28 | B32: Электрика и свет | C32: Медный ВВГнг(А)-LS 3×1,5 мм² | D32: 70 | E32: м | F32: 320 | G32: 400 | H32: 500 | I32: =D32*F32 -> 22400 | J32: =D32*G32 -> 28000 | K32: =D32*H32 -> 35000 | L32: Освещение; условные метры с запасом, фактический проект трасс отсутствует. | M32: Расчётный ориентир; прайс не проверен
A33: 29 | B33: Электрика и свет | C33: Медный ВВГнг(А)-LS 3×2,5 мм² | D33: 180 | E33: м | F33: 520 | G33: 650 | H33: 812 | I33: =D33*F33 -> 93600 | J33: =D33*G33 -> 117000 | K33: =D33*H33 -> 146160 | L33: Розетки, отдельные линии духовки/ПММ/стиральной машины; без повторного учёта духовки в 3×4. | M33: Расчётный ориентир; прайс не проверен
A34: 30 | B34: Электрика и свет | C34: Медный ВВГнг(А)-LS 3×6 мм² | D34: 20 | E34: м | F34: 1240 | G34: 1550 | H34: 1938 | I34: =D34*F34 -> 24800 | J34: =D34*G34 -> 31000 | K34: =D34*H34 -> 38760 | L34: Предварительно отдельная однофазная линия варочной панели; сечение/защита после проверки мощности и прокладки. | M34: Расчётный ориентир; прайс не проверен
A35: 31 | B35: Электрика и свет | C35: Щит, автоматика, УЗО/дифзащита, шины, реле | D35: 1 | E35: компл. | F35: 136000 | G35: 170000 | H35: 212500 | I35: =D35*F35 -> 136000 | J35: =D35*G35 -> 170000 | K35: =D35*H35 -> 212500 | L35: Ориентир на щит 36 модулей с резервом; расчёт и спецификацию делает электрик. Счётчик не включён. | M35: Расчётный ориентир; прайс не проверен
A36: 32 | B36: Электрика и свет | C36: Подрозетники, распредкоробки, трубы/гофра, крепёж | D36: 1 | E36: компл. | F36: 36000 | G36: 45000 | H36: 56250 | I36: =D36*F36 -> 36000 | J36: =D36*G36 -> 45000 | K36: =D36*H36 -> 56250 | L36: Не прокладывать кабель в несущем бетоне по произвольным штрабам. | M36: Расчётный ориентир; прайс не проверен
A37: 33 | B37: Электрика и свет | C37: Механизмы розеток/выключателей и рамки | D37: 32 | E37: мех. | F37: 1600 | G37: 2000 | H37: 2500 | I37: =D37*F37 -> 51200 | J37: =D37*G37 -> 64000 | K37: =D37*H37 -> 80000 | L37: Количество предварительное; не 32 группы щита. | M37: Расчётный ориентир; прайс не проверен
A38: 34 | B38: Электрика и свет | C38: Светильники и рабочая подсветка | D38: 1 | E38: компл. | F38: 80000 | G38: 100000 | H38: 125000 | I38: =D38*F38 -> 80000 | J38: =D38*G38 -> 100000 | K38: =D38*H38 -> 125000 | L38: Простые накладные светильники, бра, LED кухни; крупная бытовая техника исключена. | M38: Расчётный ориентир; прайс не проверен
A39: 35 | B39: Вода и канализация | C39: Труба PEX/PE-RT системы питьевой воды | D39: 40 | E39: м | F39: 560 | G39: 700 | H39: 875 | I39: =D39*F39 -> 22400 | J39: =D39*G39 -> 28000 | K39: =D39*H39 -> 35000 | L39: Метраж и диаметры примерные. Один совместимый комплект труб/фитингов; горячая вода по паспорту. | M39: Расчётный ориентир; прайс не проверен
A40: 36 | B40: Вода и канализация | C40: Пресс-фитинги, коллекторы, краны, фильтры, крепления | D40: 1 | E40: компл. | F40: 64000 | G40: 80000 | H40: 100000 | I40: =D40*F40 -> 64000 | J40: =D40*G40 -> 80000 | K40: =D40*H40 -> 100000 | L40: Редукторы — по замеру давления; доступ к обслуживаемым соединениям; опрессовка до зашивки. | M40: Расчётный ориентир; прайс не проверен
A41: 37 | B41: Вода и канализация | C41: Канализационные трубы 50/110 и фасонные части | D41: 1 | E41: компл. | F41: 24000 | G41: 30000 | H41: 37500 | I41: =D41*F41 -> 24000 | J41: =D41*G41 -> 30000 | K41: =D41*H41 -> 37500 | L41: Кухня и санузел на местах; условно DN50 до 8 м, DN110 до 2 м, ревизии и фитинги. | M41: Расчётный ориентир; прайс не проверен
...

Sheet Итог
A1: Смета: реальный расчёт и целевой лимит
A2: База: кухня на месте, ванна, ламинат, обычная кровать, потолок гостиной и одна условная стена с шумоизоляцией, две двери 2600 мм. Цели 7 млн — лимиты для запроса КП, а не подтверждённая корзина.
A4: Статья | B4: Низкий сценарий | C4: Базовый сценарий | D4: Высокий сценарий | E4: Цель 7 млн
A5: Работа | B5: =SUMIF('Покупки'!$B$5:$B$62,A5,'Покупки'!$I$5:$I$62) -> 2050000 | C5: =SUMIF('Покупки'!$B$5:$B$62,A5,'Покупки'!$J$5:$J$62) -> 2050000 | D5: =SUMIF('Покупки'!$B$5:$B$62,A5,'Покупки'!$K$5:$K$62) -> 2050000 | E5: 2050000
A6: Основания и стены | B6: =SUMIF('Покупки'!$B$5:$B$62,A6,'Покупки'!$I$5:$I$62) -> 445360 | C6: =SUMIF('Покупки'!$B$5:$B$62,A6,'Покупки'!$J$5:$J$62) -> 556700 | D6: =SUMIF('Покупки'!$B$5:$B$62,A6,'Покупки'!$K$5:$K$62) -> 695875 | E6: 480000
A7: Полы и плитка | B7: =SUMIF('Покупки'!$B$5:$B$62,A7,'Покупки'!$I$5:$I$62) -> 621200 | C7: =SUMIF('Покупки'!$B$5:$B$62,A7,'Покупки'!$J$5:$J$62) -> 776500 | D7: =SUMIF('Покупки'!$B$5:$B$62,A7,'Покупки'!$K$5:$K$62) -> 970625 | E7: 620000
A8: Шумоизоляция и потолки | B8: =SUMIF('Покупки'!$B$5:$B$62,A8,'Покупки'!$I$5:$I$62) -> 424680 | C8: =SUMIF('Покупки'!$B$5:$B$62,A8,'Покупки'!$J$5:$J$62) -> 530850 | D8: =SUMIF('Покупки'!$B$5:$B$62,A8,'Покупки'!$K$5:$K$62) -> 663562.5 | E8: 500000
A9: Электрика и свет | B9: =SUMIF('Покупки'!$B$5:$B$62,A9,'Покупки'!$I$5:$I$62) -> 444000 | C9: =SUMIF('Покупки'!$B$5:$B$62,A9,'Покупки'!$J$5:$J$62) -> 555000 | D9: =SUMIF('Покупки'!$B$5:$B$62,A9,'Покупки'!$K$5:$K$62) -> 693670 | E9: 500000
A10: Вода и канализация | B10: =SUMIF('Покупки'!$B$5:$B$62,A10,'Покупки'!$I$5:$I$62) -> 176000 | C10: =SUMIF('Покупки'!$B$5:$B$62,A10,'Покупки'!$J$5:$J$62) -> 220000 | D10: =SUMIF('Покупки'!$B$5:$B$62,A10,'Покупки'!$K$5:$K$62) -> 275000 | E10: 200000
A11: Сантехника | B11: =SUMIF('Покупки'!$B$5:$B$62,A11,'Покупки'!$I$5:$I$62) -> 416000 | C11: =SUMIF('Покупки'!$B$5:$B$62,A11,'Покупки'!$J$5:$J$62) -> 520000 | D11: =SUMIF('Покупки'!$B$5:$B$62,A11,'Покупки'!$K$5:$K$62) -> 650000 | E11: 450000
A12: Двери | B12: =SUMIF('Покупки'!$B$5:$B$62,A12,'Покупки'!$I$5:$I$62) -> 304000 | C12: =SUMIF('Покупки'!$B$5:$B$62,A12,'Покупки'!$J$5:$J$62) -> 380000 | D12: =SUMIF('Покупки'!$B$5:$B$62,A12,'Покупки'!$K$5:$K$62) -> 532000 | E12: 300000
A13: Мебель и текстиль | B13: =SUMIF('Покупки'!$B$5:$B$62,A13,'Покупки'!$I$5:$I$62) -> 1228500 | C13: =SUMIF('Покупки'!$B$5:$B$62,A13,'Покупки'!$J$5:$J$62) -> 1495000 | D13: =SUMIF('Покупки'!$B$5:$B$62,A13,'Покупки'!$K$5:$K$62) -> 1933750 | E13: 1050000
A14: Логистика | B14: =SUMIF('Покупки'!$B$5:$B$62,A14,'Покупки'!$I$5:$I$62) -> 144000 | C14: =SUMIF('Покупки'!$B$5:$B$62,A14,'Покупки'!$J$5:$J$62) -> 180000 | D14: =SUMIF('Покупки'!$B$5:$B$62,A14,'Покупки'!$K$5:$K$62) -> 225000 | E14: 150000
A15: Расходы без резерва | B15: =SUM(B5:B14) -> 6253740 | C15: =SUM(C5:C14) -> 7264050 | D15: =SUM(D5:D14) -> 8689482.5 | E15: =SUM(E5:E14) -> 6300000
A16: Резерв | B16: ='Исходные'!$B$6 -> 700000 | C16: ='Исходные'!$B$6 -> 700000 | D16: ='Исходные'!$B$6 -> 700000 | E16: ='Исходные'!$B$6 -> 700000
A17: Всего с резервом | B17: =B15+B16 -> 6953740 | C17: =C15+C16 -> 7964050 | D17: =D15+D16 -> 9389482.5 | E17: =E15+E16 -> 7000000
A18: Остаток лимита (минус = превышение) | B18: ='Исходные'!$B$5-B17 -> 46260 | C18: ='Исходные'!$B$5-C17 -> -964050 | D18: ='Исходные'!$B$5-D17 -> -2389482.5 | E18: ='Исходные'!$B$5-E17 -> 0
A20: Не включены: крупная техника, лоджия, перенос кухни/стояков, проёмы, стеклянная перепланировка, шкаф-кровать, паркет, новая входная дверь/окна/радиаторы, кондиционер и тёплый пол. Сложная новая вентиляция и неподтверждённые спецработы требуют отдельного КП. Финишный ровнитель предполагает пригодную базовую стяжку.

Sheet Опции
A1: Изменения к базовому сценарию
A2: Эти строки не включены в итог и не суммируются автоматически. Положительные суммы — условные доплаты; непроверенная перепланировка не имеет подтверждённой цены.
A4: Опция | B4: Изменение, ₸ | C4: Основание / условие
A5: Инженерная доска вместо ламината | B5: 436500 | C5: 23 × (22 000 − 6 500) + 80 000; цены условные, выбранная технология уточняется.
A6: Шкаф-кровать вместо обычного корпуса | B6: 550000 | C6: 650 000 − 100 000; матрас остаётся. Не вычитать автоматически обычный шкаф.
A7: Третья дверь 2600 мм | B7: 190000 | C7: Если нужна дверь в кухню; лимит комплекта, труд по договору.
A8: Два новых водосчётчика при необходимости | B8: 24000 | C8: 2 × 12 000; в базовой смете не покупаются. Оформление и пломбировка не оценены.
A9: Каждый дополнительный м² акустической стены | B9: 12000 | C9: Материалы условной системы; площадь определить после осмотра, труд проверить по договору.
A10: Базовая стяжка 50 мм, если её нет | B10: 249900 | C10: Пример: 38,8 × 50 × 1,8 кг/м²/мм × 1,05 / 25 = 147 мешков × 1 700. Проверить конструкцию/нагрузку/рецептуру; не монтажное задание.
A11: Оплата работы по 38,8 вместо 41 м² | B11: -110000 | C11: (38,8 − 41) × 50 000; только если это согласованная договорная площадь.
A12: Частичный проём кухни и стекло | B12: Нужно КП | C12: Не включено; тип стены неизвестен. Сначала конструктивная проверка, затем отдельная спецификация и КП; цену не подтверждаю.

Sheet Инженерия
A1: Задание электрику и сантехнику
A2: Предварительно 230 В, одна фаза. Это не монтажная схема. Сечения и защиту назначают по расчёту, способу прокладки, вводу и паспортам. Подтвердить выделенную мощность до покупки панели/духовки.
A4: Линия / вопрос | B4: Метраж / параметр | C4: Защита / нагрузка | D4: Проверка
A5: Освещение | B5: 70 м: 3×1,5 | C5: Часто до 10 А | D5: Уточнить трассы, нагрузки, прокладку и светильники
A6: Розетки + духовка + отдельные машины | B6: 180 м: 3×2,5 | C6: Обычно 16 А | D6: Метры всех этих линий уже в одной строке; духовка повторно не добавляется
A7: Варочная панель 7,2 кВт | B7: 20 м: 3×6 | C7: 32 А как кандидат | D7: 7 200 / 230 ≈ 31,3 А; проверить допустимый ток при конкретной прокладке
A8: Духовка 3,5 кВт | B8: Входит в 180 м 3×2,5 | C8: 16 А при подтверждении | D8: 3 500 / 230 ≈ 15,2 А; по паспорту устройства
A9: Совместная мощность панели и духовки | B9: 10,7 кВт | C9: ≈46,5 А при 230 В | D9: Если ввод 32 А, нужна другая согласованная схема/ограничение мощности
A10: 3×4 мм² | B10: Не закупать по умолчанию | C10: По расчёту | D10: Если потребуется, заменяет соответствующий метраж 3×2,5
A11: Защитное отключение | B11: Тип A, 30 мА — предмет проекта | C11: По схеме/паспорту | D11: Инверторным устройствам могут требоваться другие типы. Проверить PE, N и ввод.
A12: Счётчики | B12: Проверить комплект застройщика | C12: Без автоматической замены | D12: Паспорта, поверка, номера, пломбы и порядок ввода; электрический/тепловой прибор не оценены

Sheet Источники
A1: Источники и запрос коммерческих предложений
A2: 13.10.2026. Отсутствие доступа не заменяется выдуманными прайсами. Адреса магазинов, остатки и минимальные цены не установлены. Примеры марок в записке — кандидаты для сравнения, не проверенные предложения.
A4: Источник | B4: Ссылка / происхождение | C4: Что получено | D4: Статус
A5: Ставка работы | B5: Сообщение пользователя | C5: 50 000 ₸/м²; состав основных работ подтверждён | D5: Подтверждено пользователем
A6: Площади | B6: Ранее предоставленная схема | C6: 20,5 + 8,9 + 4,3 + 5,1 = 38,8 м² | D6: Экспликация; натурный обмер не выполнен
A7: Товары: все цены | B7: Расчётные допущения | C7: Ни один товарный прайс не прочитан; объёмы предварительные | D7: Не проверено
A8: Каталог для запроса | B8: https://12.kz/ | C8: CONNECT HTTP 403, повторная проверка без результата | D8: Цена/наличие не получены
A9: Каталог для запроса | B9: https://akvilon.kz/ | C9: CONNECT HTTP 403 | D9: Доставку в Астану проверить
A10: Каталог для запроса | B10: https://leroymerlin.kz/ | C10: CONNECT HTTP 403 | D10: Актуальный ассортимент/условия не установлены
A11: Продавцы для сравнения | B11: https://satu.kz/ | C11: CONNECT HTTP 403 | D11: Отдельные продавцы и документы не проверены
A12: Поиск | B12: Google / Bing | C12: CONNECT HTTP 403 | D12: Рыночное сравнение не выполнено
A15: Текст запроса: «Прошу цену по приложенной ведомости для доставки в Астану. Укажите производителя/артикул, единицу и упаковку, фактическое количество, цену с налогами, наличие, срок поставки, доставку/подъём, гарантию и возврат. Замены согласовать отдельно; приложить паспорта/документы. Двери: полотно 2600 мм, цена полного комплекта. Акустика: спецификация всей системы. Работа и сборка: указать, что уже входит».
